Workbook

Sheet Tổng quan
A1: Smart Ops Engine — Use case & Test case
A2: Sinh tự động từ docs/*.md bằng tools/scripts/build_test_docs.py — sửa Markdown rồi chạy lại.
A4: Chỉ số | B4: Giá trị
A5: Use case (v3) | B5: =COUNTA('Use case'!B2:B500)
A6: Bước / luồng use case | B6: =COUNTA('Use case - Từng bước'!A2:A2000)
A7: Test case v3 | B7: =COUNTA('Test case v3'!B2:B533)
A8: Test case v1 (legacy) | B8: =COUNTA('Test case v1 (legacy)'!B2:B142)
A9: Test case v3 — Pass | B9: =COUNTIF('Test case v3'!M2:M533,"Pass")
A10: Test case v3 — Fail | B10: =COUNTIF('Test case v3'!M2:M533,"Fail")
A11: Test case v3 — Chưa chạy | B11: =COUNTIF('Test case v3'!M2:M533,"Chưa chạy")
A12: Test case v3 — Ưu tiên P1 | B12: =COUNTIF('Test case v3'!K2:K533,"P1*")
A13: Test case v1 — Pass | B13: =COUNTIF('Test case v1 (legacy)'!M2:M142,"Pass")
A14: Test case v1 — Chưa chạy | B14: =COUNTIF('Test case v1 (legacy)'!M2:M142,"Chưa chạy")
A16: Các sheet
A17: Use case | B17: Mỗi dòng một use case: actor, kích hoạt, tiền/hậu điều kiện, luồng chính/thay thế/ngoại lệ, BR, test case liên quan.
A18: Use case - Từng bước | B18: Mỗi dòng một bước/luồng của use case — dùng để soi chi tiết hoặc lọc theo UC.
A19: Test case v3 | B19: Test case bản .NET 8 microservices (API, Integration, E2E UI, Security, Performance, Messaging). Ô vàng để ghi kết quả.
A20: Test case v1 (legacy) | B20: Test case bản Spring Boot v1 đang chạy (Backend + Frontend theo 9 module).
A21: Truy vết | B21: Thống kê use case / test case / ưu tiên / kết quả theo phân hệ (công thức, tự cập nhật).
A22: Công việc (workplan) | B22: Phân chia hạng mục ↔ thư mục ↔ SRS ↔ test case ↔ mốc M1–M5 và việc nợ của M1.
A24: Cách ghi kết quả
A25: Chọn cột 'Trạng thái' (Chưa chạy / Pass / Fail / Blocked / Skip); điền 'Kết quả thực tế', 'Người test', 'Ngày test'.
A26: Ưu tiên: P1 = bắt buộc pass trước khi phát hành; P2 = nên pass; P3 = có thể hoãn.
A27: Mã TC theo dạng TC-<PHÂN HỆ>-<TẦNG>-<SỐ>: API/INT = backend, E2E = giao diện, SEC/PERF = phi chức năng.

Sheet Use case
A1: STT | B1: Mã UC | C1: Tên use case | D1: Phân hệ | E1: Actor chính | F1: Actor phụ | G1: Ưu tiên | H1: Tần suất | I1: Kích hoạt | J1: Tiền điều kiện | K1: Luồng chính | L1: Luồng thay thế | M1: Luồng ngoại lệ | N1: Hậu điều kiện | O1: Business rule / NFR | P1: Test case liên quan | Q1: Nguồn
A2: 1 | B2: UC-IDN-01 | C2: Đăng nhập hệ thống | D2: Identity | E2: Người dùng (ADMIN / OPERATOR / VIEWER) | F2: Identity Service, Audit Service | G2: Must | H2: nhiều lần/ngày | I2: Người dùng mở ứng dụng mà chưa có phiên hợp lệ | J2: Tài khoản đã được ADMIN tạo và đang hoạt động; người dùng truy cập được `https://soe.example.com` | K2: 1. Hệ thống hiển thị trang đăng nhập với ô “Tên đăng nhập”, “Mật khẩu” và nút “Đăng nhập”. 2. Người dùng nhập thông tin và bấm “Đăng nhập”. 3. Frontend validate: cả hai ô bắt buộc, `username` đúng định dạng. Không hợp lệ → hiện lỗi tại ô, dừng. 4. Frontend gọi `POST /api/v1/auth/login`. 5. Gateway kiểm tra rate limit (5 lần/phút/IP) và chuyển tiếp. 6. Identity tìm người dùng, xác minh mật khẩu bằng Argon2id. 7. Identity đặt lại `failedLoginCount`, cập nhật `lastLoginAt`, phát hành access token (15 phút) và refresh token (cookie `HttpOnly`), phát `UserLoggedInV1`. 8. Frontend lưu access token trong bộ nhớ, khởi tạo kết nối SignalR, điều hướng tới Dashboard (hoặc `returnUrl` nội bộ). 9. Audit ghi `LOGIN_SUCCEEDED`. | L2: - A1 — Bắt buộc đổi mật khẩu: bước 7 trả `mustChangePassword = true` → frontend mở hộp thoại đổi mật khẩu và chặn điều hướng cho tới khi đổi xong (UC-IDN-03). - A2 — Còn phiên hợp lệ: ở bước 1, nếu cookie refresh còn hạn, frontend gọi `/auth/refresh` và vào thẳng Dashboard. - A3 — Có `returnUrl`: sau khi đăng nhập, điều hướng tới đường dẫn nội bộ đã lưu (chỉ nhận đường dẫn bắt đầu bằng `/`). | M2: - E1 — Sai thông tin: Identity tăng `failedLoginCount`, phát `UserLoginFailedV1`, trả `401 SOE-IDN-401`; frontend hiện “Tên đăng nhập hoặc mật khẩu không đúng.” (không nói rõ sai ở đâu — BR-IDN-001). - E2 — Sai 5 lần: tài khoản bị khóa 15 phút, trả `423 SOE-IDN-423`; frontend hiện đếm ngược; Audit ghi `ACCOUNT_LOCKED`. - E3 — Tài khoản bị vô hiệu hóa: trả `403 SOE-IDN-403` “Tài khoản đã bị vô hiệu hóa.” - E4 — Vượt rate limit: `429` + `Retry-After`; frontend hiện “Bạn thử quá nhiều lần, vui lòng đợi {n} giây.” - E5 — Identity không phản hồi: gateway trả `503`; frontend hiện “Hệ thống tạm thời không khả dụng, vui lòng thử lại.” | N2: Thành công: người dùng có phiên, access token 15 phút, refresh token 7 ngày; audit ghi nhận. Thất bại: không phát hành token; số lần sai được ghi nhận. | O2: BR liên quan: BR-IDN-001, 002, 006; NFR: NFR-SEC-004, 005, 006; đăng nhập p95 ≤ 700 ms | P2: TC-IDN-API-001…010, TC-IDN-E2E-001…004, TC-IDN-SEC-001…005 | Q2: UC-01_auth.md
A3: 2 | B3: UC-IDN-02 | C3: Duy trì phiên & đăng xuất | D3: Identity | E3: Người dùng | F3: Identity | I3: Access token hết hạn, hoặc người dùng bấm “Đăng xuất” | J3: Đang có phiên hợp lệ | K3: 1. Frontend gọi API nghiệp vụ và nhận `401`. 2. Interceptor tạm giữ mọi request đang chờ (single-flight) và gọi `POST /auth/refresh` (cookie tự gửi). 3. Identity xác minh hash refresh token, kiểm tra chưa dùng và chưa thu hồi. 4. Identity đánh dấu token cũ đã dùng, phát hành access token mới + refresh token mới cùng `FamilyId`. 5. Frontend cập nhật token trong bộ nhớ và gửi lại các request đang chờ. | L3: - A1 — Đăng xuất chủ động: người dùng bấm “Đăng xuất” → `POST /auth/logout` → thu hồi refresh token, xóa cookie, đóng SignalR, xóa cache React Query, chuyển về `/login`. - A2 — Hết hạn phiên do không thao tác: sau 30 phút không tương tác, frontend tự đăng xuất và hiện thông báo “Phiên làm việc đã kết thúc”. | M3: - E1 — Refresh token hết hạn/không hợp lệ: `401 SOE-IDN-402`; frontend chuyển về `/login` kèm `returnUrl`. - E2 — Phát hiện tái sử dụng token: Identity thu hồi toàn bộ `FamilyId`, ghi `TOKEN_REUSE_DETECTED`, trả `401`; mọi thiết bị của người dùng bị đăng xuất. - E3 — Người dùng bị vô hiệu hóa giữa phiên: refresh bị từ chối; token cũ hết hiệu lực trong tối đa 15 phút. - E4 — Đổi mật khẩu ở thiết bị khác: mọi refresh token bị thu hồi (BR-IDN-004) → E1. | N3: phiên được gia hạn liền mạch hoặc chấm dứt sạch (không còn token, không còn cache). | O3: BR: BR-IDN-003, 004, 005, 008; NFR: NFR-SEC-005 | P3: TC-IDN-API-011…018, TC-IDN-SEC-006…009 | Q3: UC-01_auth.md
A4: 3 | B4: UC-IDN-03 | C4: Đổi mật khẩu | D4: Identity | E4: Người dùng bất kỳ | I4: Người dùng chọn “Đổi mật khẩu”, hoặc hệ thống yêu cầu (`mustChangePassword`) | J4: đã đăng nhập | K4: 1. Người dùng mở hộp thoại đổi mật khẩu. 2. Nhập mật khẩu hiện tại, mật khẩu mới, xác nhận mật khẩu mới. 3. Frontend validate: ≥ 12 ký tự, có chữ và số, hai ô mới khớp nhau, khác mật khẩu hiện tại; hiện thanh đo độ mạnh. 4. Gọi `PUT /api/v1/me/password`. 5. Identity xác minh mật khẩu hiện tại, kiểm tra chính sách và danh sách mật khẩu yếu, cập nhật hash và `PasswordChangedAt`, thu hồi toàn bộ refresh token. 6. Frontend nhận `204`, hiện toast, đăng xuất và yêu cầu đăng nhập lại bằng mật khẩu mới. 7. Audit ghi `USER_PASSWORD_CHANGED`. | M4: - E1 — Sai mật khẩu hiện tại: `401`; hiện lỗi tại ô mật khẩu hiện tại. - E2 — Mật khẩu mới không đạt chính sách/nằm trong danh sách yếu: `400 SOE-IDN-400` kèm `errors.newPassword`. - E3 — Mật khẩu mới trùng mật khẩu cũ: `400` với thông báo riêng (BR-IDN-007). | N4: mật khẩu mới có hiệu lực; mọi phiên cũ bị thu hồi. | P4: TC-IDN-API-019…024, TC-IDN-E2E-005 | Q4: UC-01_auth.md
A5: 4 | B5: UC-IDN-04 | C5: Quản lý người dùng | D5: Identity | E5: ADMIN | I5: ADMIN mở màn hình “Người dùng” | J5: đăng nhập với vai trò ADMIN | K5: 1. ADMIN mở màn hình `Users`, thấy danh sách phân trang có bộ lọc vai trò/trạng thái. 2. Bấm “Thêm người dùng”, nhập `username`, họ tên, email, vai trò. 3. Frontend validate theo bảng quy tắc (SRS 01 §6). 4. Gọi `POST /api/v1/users`. 5. Identity tạo tài khoản với mật khẩu tạm, đặt `mustChangePassword = true`. 6. Hệ thống hiển thị mật khẩu tạm một lần duy nhất kèm nút sao chép và cảnh báo không hiển thị lại. 7. Audit ghi `USER_CREATED`. | L5: - A1 — Sửa người dùng: đổi họ tên/email/vai trò → `PUT /users/{id}`; đổi vai trò làm token hiện tại của người đó mất quyền ở lần refresh kế tiếp. - A2 — Vô hiệu hóa/kích hoạt: `PUT /users/{id}/status`; vô hiệu hóa kéo theo thu hồi mọi phiên. - A3 — Đặt lại mật khẩu: `POST /users/{id}/reset-password` → mật khẩu tạm mới, `mustChangePassword = true`. - A4 — Buộc đăng xuất: `POST /users/{id}/revoke-sessions`. | M5: - E1 — Trùng username/email: `409 SOE-IDN-409`, lỗi gắn vào đúng ô. - E2 — Hạ quyền/vô hiệu hóa ADMIN cuối cùng: `422 SOE-IDN-422` “Không thể vô hiệu hóa quản trị viên cuối cùng.” (FR-IDN-015). - E3 — ADMIN tự vô hiệu hóa chính mình: chặn ở backend với cùng mã lỗi. - E4 — Người dùng không tồn tại: `404`. | N5: danh sách người dùng phản ánh thay đổi; mọi thao tác có bản ghi audit. | O5: BR: BR-IDN-006, 008; NFR: NFR-SEC-008, NFR-SEC-012 | P5: TC-IDN-API-025…036, TC-IDN-E2E-006…009, TC-GW-SEC-010 (VIEWER/OPERATOR bị 403) | Q5: UC-01_auth.md
A6: 5 | B6: UC-INV-01 | C6: Thêm node mới | D6: Inventory | E6: ADMIN | F6: Inventory, Máy chủ đích (khi kiểm tra kết nối), Monitoring, Audit | G6: Must | H6: vài lần/tuần | I6: ADMIN bấm “Thêm máy chủ” ở màn hình `Nodes` | J6: ADMIN đã đăng nhập; đã có thông tin SSH của máy chủ cần giám sát | K6: 1. Hệ thống mở modal “Thêm máy chủ mới” với hai tab xác thực: Password (mặc định) và SSH Key; ba checkbox giám sát CPU/RAM/Disk mặc định bật. 2. ADMIN nhập: tên, IP/hostname, port (mặc định 22), tài khoản SSH, credential theo tab đang chọn, đường mount đĩa (mặc định `/`), mô tả, tag (tùy chọn), chu kỳ quét riêng (tùy chọn). 3. Frontend validate theo schema zod (SRS 02 §6); lỗi hiển thị dưới từng ô, nút “Lưu” bị khóa. 4. ADMIN bấm “Kiểm tra kết nối” (khuyến nghị) → `POST /nodes/{tạm}/test-connection` hoặc kiểm tra kèm khi lưu (`testConnectionFirst = true`). 5. Inventory mở phiên SSH thử, lấy fingerprint host key, chạy một lệnh vô hại, trả kết quả kèm thời lượng. 6. ADMIN bấm “Lưu”; frontend gọi `POST /api/v1/nodes`. 7. Gateway kiểm tra vai trò ADMIN và rate limit ghi. 8. Inventory validate nghiệp vụ, kiểm tra trùng `(host, port)` và trùng `name`. 9. Inventory mã hóa credential bằng AES-256-GCM (một lần duy nhất, tại tầng Infrastructure), ghim fingerprint, lưu node + bản ghi outbox trong cùng transaction. 10. Trả `201 Created` với `NodeResponse` không chứa credential. 11. Outbox publisher phát `NodeCreatedV1`; Monitoring thêm vào read model và xếp lịch quét; Audit ghi `NODE_CREATED`. 12. Frontend đóng modal, thêm node vào danh sách, hiện toast “Đã thêm máy chủ {tên}”. | L6: - A1 — Dùng SSH Key: ADMIN chuyển tab SSH Key, dán private key (và passphrase nếu có); ô Password ẩn đi; validate bắt đầu bằng `-----BEGIN`, ≤ 16 KB. - A2 — Bỏ qua kiểm tra kết nối: node vẫn được tạo; lần quét đầu sẽ phát hiện lỗi và mở sự cố `NODE_UNREACHABLE`. - A3 — Tạo node ở trạng thái tắt giám sát: bỏ chọn “Giám sát”; node không được xếp lịch cho tới khi bật. - A4 — Nhập hàng loạt bằng CSV (Could): tải lên tệp, hệ thống báo lỗi theo từng dòng, chỉ tạo các dòng hợp lệ. | M6: - E1 — Trùng host:port: `409 SOE-INV-409`; frontend gắn lỗi vào ô Host: “Đã có node sử dụng 192.168.1.10:22.” - E2 — Trùng tên: `409 SOE-INV-410`. - E3 — Dữ liệu không hợp lệ (port 70000, host có ký tự lạ): `400` kèm `errors` theo field. - E4 — Kiểm tra kết nối thất bại: hiển thị nguyên nhân theo `failureKind` (sai mật khẩu, timeout, từ chối kết nối) kèm gợi ý; nếu bật `testConnectionFirst` thì trả `422` và không tạo node. - E5 — Người dùng không phải ADMIN: `403` (OPERATOR/VIEWER không thấy nút, nhưng gọi thẳng API vẫn bị chặn). - E6 — Mất kết nối khi đang lưu: transaction rollback; không có node “nửa vời”, không có event phát đi (nhờ outbox). | N6: Thành công: node tồn tại, credential được mã hóa, fingerprint đã ghim, Monitoring bắt đầu quét từ chu kỳ kế tiếp, có bản ghi audit. Thất bại: không tạo node, không phát event. | O6: BR: BR-INV-001…003, 006, 007; NFR: NFR-SEC-003, NFR-SEC-013, NFR-PERF-002 | P6: TC-INV-API-001…015, TC-INV-E2E-001…006, TC-INV-SEC-001…004 | Q6: UC-02_node.md
A7: 6 | B7: UC-INV-02 | C7: Sửa thông tin node | D7: Inventory | E7: ADMIN | I7: ADMIN bấm biểu tượng sửa trên hàng node | J7: node tồn tại | K7: 1. Hệ thống mở modal “Cập nhật máy chủ” với dữ liệu hiện tại được điền sẵn; ô credential hiển thị `••••••••`. 2. ADMIN sửa các trường cần thiết (tên, mô tả, cờ giám sát, mount path, chu kỳ riêng, tag). 3. Frontend chỉ gửi credential khi người dùng thực sự nhập giá trị mới (`changeCredential = true`). 4. Gọi `PUT /api/v1/nodes/{id}`; Inventory validate, kiểm tra trùng, cập nhật, phát `NodeUpdatedV1` với `changedFields[]`. 5. Monitoring cập nhật read model; Audit ghi `NODE_UPDATED` kèm diff (credential hiển thị `*`). 6. Frontend đóng modal, cập nhật hàng trong bảng, hiện toast. | L7: - A1 — Đổi credential: nhập giá trị mới → Inventory mã hóa lại và ghi đè; lần quét kế tiếp dùng credential mới. - A2 — Đổi host/port: fingerprint đã ghim bị xóa; hệ thống cảnh báo cần ghim lại ở lần kết nối tới. - A3 — Tắt một loại metric: bỏ chọn CPU → Monitoring không thu CPU nữa; Incident đóng các sự cố `CPU_HIGH` đang mở của node. | M7: - E1 — Node đã bị xóa bởi người khác: `404 SOE-INV-404`; frontend làm mới danh sách. - E2 — Xung đột chỉnh sửa đồng thời: `409` (optimistic concurrency); frontend đề nghị tải lại dữ liệu mới nhất. - E3 — Giá trị mới trùng node khác: `409` như UC-INV-01/E1. | N7: thông tin node được cập nhật, credential cũ giữ nguyên nếu không đổi. | P7: TC-INV-API-016…024, TC-INV-E2E-007…009 | Q7: UC-02_node.md
A8: 7 | B8: UC-INV-03 | C8: Bật/tắt giám sát node | D8: Inventory | E8: OPERATOR hoặc ADMIN | I8: Người dùng gạt công tắc “Giám sát” trên hàng node | K8: 1. Người dùng gạt công tắc; frontend cập nhật optimistic và gọi `PUT /nodes/{id}/monitoring`. 2. Inventory cập nhật `isActive`, phát `NodeMonitoringToggledV1`. 3. Monitoring ngừng (hoặc bắt đầu) xếp lịch quét cho node từ chu kỳ kế tiếp. 4. Khi tắt: Incident đóng mọi sự cố chưa đóng của node với lý do “Node ngừng giám sát”; Metrics đặt `status = MONITORING_OFF`. 5. Frontend hiện toast; các chỉ số của node chuyển sang trạng thái “Đang tắt” thay vì hiển thị số cũ. | M8: - E1 — API lỗi: rollback trạng thái công tắc, hiện toast lỗi. - E2 — VIEWER thao tác: không thấy công tắc; gọi thẳng API nhận `403`. | N8: node được/không được xếp lịch quét; sự cố liên quan đã đóng. | O8: BR: BR-INV-005 | P8: TC-INV-API-025…028, TC-INC-INT-015, TC-INV-E2E-010 | Q8: UC-02_node.md
A9: 8 | B9: UC-INV-04 | C9: Xóa node | D9: Inventory | E9: ADMIN | I9: ADMIN bấm biểu tượng thùng rác | K9: 1. Hệ thống hiển thị hộp thoại xác nhận nêu rõ tên node và hệ quả: ngừng giám sát, đóng sự cố đang mở, dữ liệu lịch sử vẫn tra cứu được trong 30 ngày. 2. ADMIN xác nhận; frontend gọi `DELETE /api/v1/nodes/{id}`. 3. Inventory đánh dấu `DeletedAt`, xóa cứng bản ghi credential, phát `NodeDeletedV1`, trả `204`. 4. Monitoring bỏ node khỏi lịch; Incident đóng sự cố chưa đóng; Metrics đánh dấu dữ liệu lưu trữ; Audit ghi `NODE_DELETED`. 5. Frontend xóa hàng khỏi bảng và hiện toast. | M9: - E1 — Node không tồn tại: `404`, làm mới danh sách. - E2 — Người dùng hủy: đóng hộp thoại, không thay đổi gì. - E3 — Message `NodeDeletedV1` xử lý muộn: một lần quét đang chạy có thể hoàn tất; Metrics/Incident bỏ qua dữ liệu của node đã xóa (BR-MET/INC). | N9: node biến mất khỏi danh sách giám sát; credential bị xóa vĩnh viễn; lịch sử vẫn tra cứu được. | O9: BR: BR-INV-004 | P9: TC-INV-API-029…033, TC-INV-E2E-011…012 | Q9: UC-02_node.md
A10: 9 | B10: UC-INV-05 | C10: Xử lý thay đổi host key | D10: Inventory | E10: ADMIN | F10: Worker giám sát, Incident, Audit | G10: Must | H10: hiếm (nhưng là tình huống bảo mật quan trọng) | I10: Worker phát hiện fingerprint khác bản đã ghim khi kết nối | J10: Node đã có `hostKeyFingerprint` được ghim | K10: 1. Worker so sánh fingerprint nhận được với bản đã ghim → khác nhau. 2. Worker hủy kết nối trước khi gửi credential, phát `NodeUnreachableV1` với `failureKind = HostKeyMismatch`. 3. Incident mở sự cố `HOST_KEY_MISMATCH` mức CRITICAL ngay lần đầu. 4. Notification gửi cảnh báo tới các kênh; Audit ghi `HOSTKEY_MISMATCH_BLOCKED`. 5. ADMIN mở màn hình node, thấy cảnh báo đỏ giải thích rủi ro (máy chủ cài lại, đổi khóa, hoặc bị tấn công trung gian). 6. ADMIN xác minh ngoài hệ thống (so sánh fingerprint trên máy chủ thật). 7. Nếu hợp lệ: ADMIN bấm “Ghim lại host key”, nhập tên node để xác nhận → `POST /nodes/{id}/host-key/pin`. 8. Inventory cập nhật fingerprint, Audit ghi `NODE_HOSTKEY_PINNED`; lần quét kế tiếp hoạt động bình thường và sự cố được tự đóng khi thu được metric. | L10: - A1 — ADMIN nghi bị tấn công: tắt giám sát node, xử lý hạ tầng, sau đó ghim lại. | M10: - E1 — Người dùng không phải ADMIN bấm ghim lại: `403`. - E2 — Node đã bị xóa trong lúc xử lý: `404`. | N10: hệ thống không bao giờ gửi credential tới máy chủ có host key lạ; hành động ghim lại có dấu vết kiểm toán. | O10: BR: BR-INV-006, BR-MON-007; NFR: NFR-SEC-013 | P10: TC-INV-SEC-005…008, TC-MON-INT-010, TC-INC-INT-012 | Q10: UC-02_node.md
A11: 10 | B11: UC-MON-01 | C11: Quét định kỳ toàn hệ thống | D11: Monitoring | E11: Scheduler (hệ thống) | F11: Worker giám sát, Inventory, Máy chủ đích, Metrics, Incident, Realtime | G11: Must | H11: mỗi 5 phút (cấu hình được) | I11: Trigger Quartz đến hạn | J11: Scheduler đang bật; có ít nhất một node `isActive`; RabbitMQ khả dụng | K11: 1. Quartz kích hoạt job `ScanCycleJob` trên đúng một instance Scheduler (cluster lock). 2. Scheduler lấy danh sách node `isActive` đến hạn quét từ read model `MonitoredNodes`. 3. Với mỗi node, phát `CheckNodeV1` (`checkId`, `nodeId`, danh sách metric cần thu, `reason = Scheduled`, TTL một chu kỳ). 4. Scheduler ghi metric `soe_scan_cycle_coverage_ratio` và thời điểm bắt đầu chu kỳ. 5. RabbitMQ phân phối message cho các Worker rảnh (competing consumers). 6. Worker nhận message, kiểm tra message chưa quá hạn, lấy thông tin node từ read model. 7. Worker gọi Inventory `GET /internal/nodes/{id}/credentials` (mTLS, scope riêng); Inventory ghi audit `CREDENTIAL_ACCESSED`. 8. Worker mở phiên SSH: kiểm tra host key khớp fingerprint đã ghim → xác thực → chạy lệnh thu CPU (`/proc/stat` hai lần cách 1 giây), RAM (`free`), Disk (`df` theo mount path). 9. Worker phân tích kết quả thành `MetricSnapshot` (0–100, hai chữ số thập phân; không đọc được ⇒ `null`), đóng phiên SSH, xóa credential khỏi bộ nhớ. 10. Worker ghi `CheckRuns` và phát `MetricCollectedV1`. 11. Metrics lưu snapshot và cập nhật `MetricLatest`; Incident đánh giá ngưỡng (UC-INC-01); Realtime đẩy dữ liệu tới client đang mở Dashboard/Node Detail. | L11: - A1 — Node có chu kỳ riêng: chỉ phát lệnh khi `now − lastCheckedAt ≥ checkIntervalSeconds`. - A2 — Node chỉ giám sát một phần: message chỉ liệt kê metric được bật; Worker chỉ chạy lệnh tương ứng. - A3 — Hàng đợi tăng cao: KEDA tăng số Worker; chu kỳ vẫn hoàn tất trong hạn. - A4 — Scheduler bị tắt bởi ADMIN: không phát lệnh; Dashboard hiển thị “Giám sát đang tạm dừng”. | M11: - E1 — SSH timeout/không kết nối được: xem UC-MON-03. - E2 — Host key không khớp: hủy kết nối, xem UC-INV-05. - E3 — Inventory không phản hồi: Worker retry theo Polly; hết retry thì message quay lại queue và được thử lại ở chu kỳ sau; cảnh báo `SoeScanCoverageLow` nếu kéo dài. - E4 — Kết quả lệnh không phân tích được: metric tương ứng `null`, ghi cảnh báo với `failureKind = ParseError`; các metric khác vẫn được lưu. - E5 — Message quá hạn: Worker bỏ qua để tránh quét dồn sau sự cố (FR-MON-016). - E6 — Worker bị dừng giữa chừng: message chưa ack quay lại queue và được xử lý lại; nhờ idempotency không sinh dữ liệu trùng. - E7 — RabbitMQ không khả dụng: Scheduler ghi outbox, phát lại khi broker phục hồi; cảnh báo hạ tầng. | N11: Thành công: mọi node active có một snapshot mới; chỉ số hệ thống cập nhật; sự cố được đánh giá. Thất bại một phần: node lỗi có bản ghi `CheckRuns` với `outcome = Failed` và sự cố tương ứng. | O11: BR: BR-MON-001…007; NFR: NFR-SCL-001, NFR-PERF-005, NFR-AVL-003, 005, 006 | P11: TC-MON-INT-001…012, TC-MON-PERF-001…004, TC-MON-CON-001…003 | Q11: UC-03_monitoring.md
A12: 11 | B12: UC-MON-02 | C12: Kiểm tra node ngay (Check now) | D12: Monitoring | E12: OPERATOR hoặc ADMIN | I12: Người dùng bấm “Kiểm tra ngay” ở màn hình Nodes hoặc Node Detail | J12: Node tồn tại và đang bật giám sát | K12: 1. Người dùng bấm nút; frontend gọi `POST /api/v1/nodes/{id}/check-now`. 2. Gateway kiểm tra vai trò OPERATOR+ và rate limit (5/phút/user, 1/30 giây/node). 3. Monitoring phát `CheckNodeV1` với `reason = Manual`, `requestedBy = userId`, trả `202 Accepted` + `checkId`. 4. Frontend hiện trạng thái “Đang kiểm tra…”, khóa nút 30 giây. 5. Worker xử lý như UC-MON-01 bước 6–11. 6. Realtime đẩy `CheckCompleted` (kèm `checkId`, kết quả, thời lượng) và `MetricCollected`. 7. Frontend cập nhật chỉ số, mở khóa nút, hiện toast “Đã cập nhật chỉ số của {node}” hoặc thông báo lỗi. | L12: - A1 — Không nhận được kết quả trong 60 giây: frontend dừng trạng thái chờ và gợi ý xem tab “Lần quét gần đây”. | M12: - E1 — Node đang tắt giám sát: `409 SOE-MON-409` “Node đang tắt giám sát.” - E2 — Gọi quá nhanh: `429`, frontend hiện “Vui lòng đợi {n} giây.” - E3 — VIEWER gọi API: `403`. - E4 — Node không tồn tại: `404`. | N12: có thêm một bản ghi quét và snapshot mới; sự cố được đánh giá lại ngay. | P12: TC-MON-API-001…008, TC-MON-E2E-001…003 | Q12: UC-03_monitoring.md
A13: 12 | B13: UC-MON-03 | C13: Xử lý node không truy cập được | D13: Monitoring | E13: Worker giám sát (hệ thống) | F13: Incident, Notification, Realtime, Kỹ sư vận hành | I13: Kết nối SSH thất bại sau các lần retry nội bộ | K13: 1. Worker thử kết nối; gặp lỗi (timeout, từ chối, xác thực sai). 2. Worker retry tối đa 2 lần trong cùng message với backoff ngắn. 3. Vẫn thất bại ⇒ phân loại `failureKind` (`ConnectTimeout`, `AuthFailed`, `HostKeyMismatch`, `CommandTimeout`, `Unknown`). 4. Worker ghi `CheckRuns` (`outcome = Failed`) và phát `NodeUnreachableV1` với thông điệp đã lọc sạch credential. 5. Incident mở sự cố tương ứng (`NODE_UNREACHABLE`, `AUTH_FAILED`, `HOST_KEY_MISMATCH`) mức CRITICAL ngay lần đầu. 6. Notification gửi cảnh báo tới các kênh phù hợp; Realtime đẩy `NodeStatusChanged`; Metrics đặt `status = UNREACHABLE`. 7. Kỹ sư vận hành nhận cảnh báo, kiểm tra máy chủ. 8. Khi máy chủ hoạt động trở lại, lần quét kế tiếp thành công ⇒ Incident tự đóng sự cố (UC-INC-04), Realtime cập nhật trạng thái. | L13: - A1 — Sai xác thực do đổi mật khẩu trên máy chủ: ADMIN cập nhật credential (UC-INV-02/A1); sự cố đóng khi quét thành công. - A2 — Máy chủ ngừng vĩnh viễn: ADMIN tắt giám sát hoặc xóa node; sự cố được đóng theo BR-INV-005. | M13: - E1 — Toàn bộ node cùng lỗi (mất mạng/firewall): số sự cố tăng đột biến → Notification gom thành thông báo digest (FR-NTF-020) và cảnh báo vận hành `SoeScanCoverageLow`. - E2 — Lỗi chập chờn: nhờ hysteresis và auto-resolve, sự cố `NODE_UNREACHABLE` đóng ngay khi quét lại thành công, tránh nhiễu. | N13: mọi lần quét thất bại đều có dấu vết chẩn đoán và đúng một sự cố mở cho mỗi node. | O13: BR: BR-INC-001, BR-MON-007; NFR: NFR-AVL-005 | P13: TC-MON-INT-013…020, TC-INC-INT-010…014, TC-NTF-INT-008 | Q13: UC-03_monitoring.md
A14: 13 | B14: UC-MET-01 | C14: Xem dashboard tổng quan | D14: Metrics | E14: VIEWER / OPERATOR / ADMIN | F14: Metrics, Incident, Monitoring, Realtime | G14: Must | H14: liên tục trong giờ làm việc | I14: Người dùng mở `/app/dashboard` (trang mặc định sau đăng nhập) | J14: Người dùng đã đăng nhập | K14: 1. Frontend tải song song: `GET /metrics/health-summary`, `GET /metrics/latest`, `GET /incidents?status=OPEN&pageSize=5`, `GET /monitoring/status` (tối đa 6 request — NFR-PERF). 2. Trong lúc chờ, hiển thị skeleton giữ đúng bố cục (tránh CLS). 3. Hệ thống hiển thị: 4. Frontend mở kết nối SignalR, tham gia nhóm `all-nodes`. 5. Mỗi khi có `MetricCollected`, cập nhật trực tiếp cache (không gọi lại API); có `IncidentOpened` thì cập nhật bộ đếm và danh sách, hiện toast. | L14: - A1 — Mất kết nối realtime: hiện chỉ báo “Đang kết nối lại”; sau 30 giây chuyển sang polling 30 giây (BR-RTM-003). - A2 — Dữ liệu cũ: node có `isStale = true` hiển thị nhãn “Dữ liệu cũ · {thời điểm}”. - A3 — Chưa có node nào: hiển thị trạng thái rỗng kèm hướng dẫn “Thêm máy chủ đầu tiên” (nút chỉ hiện với ADMIN). - A4 — Tab bị ẩn > 5 phút: tạm dừng cập nhật biểu đồ; khi quay lại thì đồng bộ bằng một lần gọi API. | M14: - E1 — API lỗi 5xx: hiển thị khối lỗi kèm nút “Thử lại”; các khối khác vẫn hiển thị bình thường. - E2 — Token hết hạn: tự refresh (UC-IDN-02); người dùng không bị gián đoạn. - E3 — Hệ thống đang bảo trì: hiện thông báo bảo trì, chỉ cho phép xem. | N14: người dùng thấy tình trạng toàn hệ thống trong ≤ 2,5 giây kể từ khi mở trang. | O14: NFR: NFR-PERF-003, 020, 021, 022; NFR-USA-002, 004 | P14: TC-MET-API-001…006, TC-MET-E2E-001…005, TC-MET-PERF-001…003 | Q14: UC-04_metrics.md
A15: 14 | B15: UC-MET-02 | C15: Xem lịch sử chỉ số một node | D15: Metrics | E15: VIEWER+ | I15: Người dùng bấm tên node ở danh sách, mở `/app/nodes/{id}` | J15: node tồn tại | K15: 1. Frontend gọi `GET /nodes/{id}`, `GET /nodes/{id}/metrics?range=24h`, `GET /nodes/{id}/metrics/summary`, `GET /incidents?nodeId={id}`. 2. Hệ thống hiển thị: thông tin node, chỉ số hiện tại, biểu đồ đường CPU/RAM/Disk 24 giờ có đường ngưỡng cảnh báo/nguy cấp, tóm tắt (trung bình/đỉnh 24h, xu hướng đĩa, dự báo đầy đĩa), danh sách sự cố của node, bảng các lần quét gần đây. 3. Người dùng đổi dải thời gian (1h / 24h / 7d / 30d); frontend gọi lại API với `range` tương ứng, giữ dữ liệu cũ làm nền (`keepPreviousData`). 4. Backend tự chọn nguồn: ≤ 24h dùng snapshot thô, > 24h dùng rollup theo giờ; trả tối đa 500 điểm kèm `resolution`. 5. Frontend vẽ biểu đồ; tooltip hiển thị thời gian theo múi giờ người dùng và giá trị trung bình/đỉnh. 6. SignalR `SubscribeNode(nodeId)`: điểm dữ liệu mới được nối vào biểu đồ 1h theo thời gian thực. | L15: - A1 — Node chưa có dữ liệu: hiển thị trạng thái rỗng “Chưa có dữ liệu giám sát” + nút “Kiểm tra ngay” (OPERATOR+). - A2 — Khoảng tùy chỉnh: người dùng chọn `from`/`to`; hệ thống áp dụng giới hạn 90 ngày. - A3 — Một metric bị tắt giám sát: biểu đồ tương ứng hiển thị thông báo “Đang không giám sát {metric}”. | M15: - E1 — Node không tồn tại/đã xóa: `404`; hiển thị “Không tìm thấy máy chủ” + nút quay lại danh sách. - E2 — Dải thời gian quá lớn: `400 SOE-MET-400`; frontend chặn từ trước và giải thích giới hạn 90 ngày. - E3 — Có điểm `null`: biểu đồ ngắt đường, tooltip ghi “Không thu được dữ liệu” (BR-MET-001). - E4 — Rời trang khi đang tải: hủy request (AbortController), không cập nhật state. | N15: người dùng thấy xu hướng tài nguyên theo dải thời gian đã chọn. | O15: NFR: NFR-PERF-004, NFR-SCL-007 | P15: TC-MET-API-007…018, TC-MET-E2E-006…010 | Q15: UC-04_metrics.md
A16: 15 | B16: UC-MET-03 | C16: Xuất dữ liệu chỉ số | D16: Metrics | E16: OPERATOR hoặc ADMIN | I16: Người dùng bấm “Xuất CSV” ở trang Node Detail | K16: 1. Người dùng chọn khoảng thời gian và bấm “Xuất CSV”. 2. Hệ thống hiển thị hộp thoại xác nhận kèm số dòng ước tính. 3. Frontend gọi `GET /nodes/{id}/metrics/export?from=&to=`. 4. Metrics xuất theo luồng (streaming) CSV với `Content-Disposition`, tối đa 100.000 dòng. 5. Trình duyệt tải tệp; Audit ghi `METRICS_EXPORTED`. | M16: - E1 — Vượt giới hạn dòng: `400` kèm thông báo đề nghị thu hẹp khoảng thời gian. - E2 — VIEWER thao tác: không thấy nút; gọi API nhận `403`. - E3 — Kết nối gián đoạn khi tải: người dùng tải lại; hệ thống không giữ trạng thái dở dang. | N16: tệp CSV được tải về; hành động có dấu vết kiểm toán. | P16: TC-MET-API-019…022, TC-AUD-INT-006 | Q16: UC-04_metrics.md
A17: 16 | B17: UC-INC-01 | C17: Phát hiện và mở sự cố | D17: Incident | E17: Incident Service (hệ thống) | F17: Monitoring, Notification, Realtime, Audit | G17: Must | H17: mỗi snapshot (≈ 500 lần/chu kỳ) | I17: Nhận `MetricCollectedV1` | J17: Có chính sách ngưỡng đang bật cho loại metric tương ứng | K17: 1. Incident nhận `MetricCollectedV1`, bỏ qua nếu `collectedAt` cũ hơn `lastProcessedAt` của node/metric. 2. Xác định chính sách áp dụng: override theo node (nếu có) → chính sách toàn cục. 3. Với mỗi metric có giá trị khác `null`, xác định mức: `NORMAL` / `WARNING` / `CRITICAL`. 4. Mức khác `NORMAL` ⇒ tăng `breachStreak`, đặt `recoveryStreak = 0`. 5. Nếu đã có sự cố chưa đóng cùng `(nodeId, type)`: tăng `occurrenceCount`, cập nhật `lastSeenAt` và `metricValue` — không tạo bản ghi mới. 6. Nếu chưa có và `breachStreak ≥ consecutiveBreaches`: mở sự cố mới với mô tả tiếng Việt theo mẫu, phát `IncidentOpenedV1` qua outbox. 7. Notification chọn kênh theo severity và bộ lọc node, gửi cảnh báo (UC-NTF-01). 8. Realtime đẩy `IncidentOpened`; Audit ghi nhận; Dashboard cập nhật bộ đếm. | L17: - A1 — Nâng cấp mức độ: sự cố đang WARNING mà giá trị vượt ngưỡng CRITICAL ⇒ nâng severity, phát `IncidentEscalatedV1`, gửi cảnh báo lại (không bị throttle chặn). - A2 — Node không liên lạc được: nhận `NodeUnreachableV1` ⇒ mở sự cố ngay lần đầu, không cần chuỗi breach. - A3 — Metric bị tắt đánh giá: bỏ qua hoàn toàn. - A4 — Nhiều metric cùng vượt ngưỡng: mỗi loại một sự cố riêng (`CPU_HIGH`, `DISK_HIGH`…), gửi cảnh báo riêng. | M17: - E1 — Message trùng lặp: inbox idempotency ⇒ không tăng `occurrenceCount` hai lần. - E2 — Xung đột đồng thời hai snapshot cùng node: optimistic concurrency, retry; ràng buộc unique ở DB bảo đảm chỉ một sự cố mở. - E3 — Giá trị vượt ngưỡng nhưng chưa đủ số lần liên tiếp: chỉ tăng `breachStreak`, chưa mở sự cố (chống nhiễu tức thời). - E4 — Node vừa bị xóa: bỏ qua message, không mở sự cố. | N17: tối đa một sự cố chưa đóng cho mỗi `(node, loại)`; cảnh báo được đưa vào hàng đợi. | O17: BR: BR-INC-001, 006, 008; NFR: NFR-AVL-003, NFR-PERF-010 | P17: TC-INC-UNIT-001…012, TC-INC-INT-001…009 | Q17: UC-05_incident.md
A18: 17 | B18: UC-INC-02 | C18: Xác nhận xử lý sự cố (Acknowledge) | D18: Incident | E18: OPERATOR / ADMIN | I18: Người dùng bấm “Xác nhận xử lý” trong danh sách hoặc chi tiết sự cố | J18: sự cố ở trạng thái `OPEN` | K18: 1. Hệ thống mở hộp thoại cho phép nhập ghi chú (≤ 500 ký tự, không bắt buộc). 2. Người dùng xác nhận; frontend cập nhật optimistic và gọi `PUT /incidents/{id}/acknowledge`. 3. Incident kiểm tra trạng thái `OPEN`, chuyển sang `ACKNOWLEDGED`, ghi `IncidentEvents`, phát `IncidentAcknowledgedV1`. 4. Realtime đẩy cập nhật cho mọi người đang xem; Audit ghi `INCIDENT_ACKNOWLEDGED`. 5. Frontend hiển thị trạng thái mới kèm tên người xác nhận và thời điểm. | M18: - E1 — Sự cố đã được người khác xác nhận/đóng: `409 SOE-INC-409`; frontend rollback optimistic và làm mới dữ liệu, hiện thông báo “Sự cố đã được {tên} xử lý.” - E2 — VIEWER thao tác: không thấy nút; gọi API nhận `403`. - E3 — Sự cố không tồn tại: `404`. | N18: sự cố có người phụ trách rõ ràng; cảnh báo lặp vẫn tính vào `occurrenceCount` nhưng không đổi trạng thái. | O18: BR: BR-INC-003 | P18: TC-INC-API-001…006, TC-INC-E2E-001…003 | Q18: UC-05_incident.md
A19: 18 | B19: UC-INC-03 | C19: Đóng sự cố (Resolve) | D19: Incident | E19: OPERATOR / ADMIN | I19: Người dùng bấm “Đóng sự cố” | J19: Sự cố ở trạng thái `OPEN` hoặc `ACKNOWLEDGED` | K19: 1. Hệ thống mở hộp thoại yêu cầu mô tả hành động xử lý (bắt buộc, 3–1000 ký tự). 2. Người dùng nhập nội dung và xác nhận; frontend validate rồi gọi `PUT /incidents/{id}/resolve`. 3. Incident chuyển trạng thái `RESOLVED`, ghi `resolvedAt`, `resolvedBy`, `resolvedSource = USER`, `resolutionAction`; ghi `IncidentEvents`; phát `IncidentResolvedV1`. 4. Notification gửi thông báo “đã đóng” tới các kênh bật tùy chọn này; Realtime cập nhật; Audit ghi `INCIDENT_RESOLVED`. 5. Frontend chuyển sự cố sang nhóm đã xử lý, cập nhật bộ đếm trên Dashboard, hiện toast. | L19: - A1 — Sự cố tái phát sau khi đóng: lần breach kế tiếp mở sự cố mới (lịch sử cũ được giữ nguyên để phân tích). - A2 — Đóng hàng loạt: chọn nhiều sự cố và đóng cùng một lý do (Could). | M19: - E1 — Sự cố đã đóng: `409`; hiện thông báo và làm mới danh sách. - E2 — Thiếu nội dung xử lý: frontend chặn; nếu gọi thẳng API thì `400` với `errors.resolutionAction`. - E3 — Nguyên nhân chưa được khắc phục: chu kỳ quét kế tiếp mở sự cố mới → người dùng thấy sự cố quay lại (hành vi đúng theo thiết kế). | N19: sự cố đóng kèm mô tả xử lý phục vụ tra cứu và tính MTTR. | O19: BR: BR-INC-003, 004, 007 | P19: TC-INC-API-007…014, TC-INC-E2E-004…006 | Q19: UC-05_incident.md
A20: 19 | B20: UC-INC-04 | C20: Tự động đóng sự cố khi hồi phục | D20: Incident | E20: Incident Service (hệ thống) | I20: Nhận snapshot có giá trị đã hồi phục, hoặc node liên lạc lại được | K20: 1. Nhận `MetricCollectedV1` với giá trị < `ngưỡng − recoveryMargin` (mặc định thấp hơn 5 điểm %). 2. Tăng `recoveryStreak`, đặt `breachStreak = 0`. 3. Khi `recoveryStreak ≥ consecutiveRecoveries` (mặc định 2) và tồn tại sự cố chưa đóng: 4. Notification gửi thông báo hồi phục (nếu kênh bật); Realtime cập nhật; Audit ghi `INCIDENT_AUTO_RESOLVED`. | L20: - A1 — Node liên lạc lại được: nhận `MetricCollectedV1` thành công ⇒ đóng ngay sự cố `NODE_UNREACHABLE` (không cần chuỗi hồi phục). - A2 — Node bị tắt giám sát/xóa: đóng mọi sự cố chưa đóng với lý do hệ thống. | M20: - E1 — Giá trị dao động quanh ngưỡng: nhờ `recoveryMargin` + `consecutiveRecoveries`, sự cố không đóng/mở liên tục (chống flapping). - E2 — Sự cố đã được người dùng đóng trước: bỏ qua, không thay đổi bản ghi. | N20: danh sách sự cố mở phản ánh đúng tình trạng thực tế mà không cần thao tác thủ công. | O20: BR: BR-INC-004, 007 | P20: TC-INC-UNIT-013…020, TC-INC-INT-010…016 | Q20: UC-05_incident.md
A21: 20 | B21: UC-INC-05 | C21: Cấu hình ngưỡng cảnh báo | D21: Incident | E21: ADMIN | I21: ADMIN mở màn hình `SystemConfig` mục “Ngưỡng cảnh báo”, hoặc mục ngưỡng riêng của một node | J21: đăng nhập vai trò ADMIN | K21: 1. Hệ thống hiển thị chính sách hiện tại cho CPU / RAM / Disk: ngưỡng cảnh báo, ngưỡng nguy cấp, số lần liên tiếp, biên hồi phục, số lần hồi phục, bật/tắt. 2. ADMIN chỉnh giá trị; frontend validate ngay (`warning < critical`, phạm vi hợp lệ). 3. (Tùy chọn) Hệ thống hiển thị xem trước: “Với dữ liệu 24 giờ qua, cấu hình này sẽ tạo N sự cố.” 4. ADMIN bấm “Lưu”, xác nhận trong hộp thoại nêu hệ quả. 5. Frontend gọi `PUT /threshold-policies/global` (hoặc `/nodes/{nodeId}`). 6. Incident lưu chính sách; áp dụng từ snapshot kế tiếp, không hồi tố sự cố đang mở. 7. Audit ghi `THRESHOLD_POLICY_UPDATED` kèm giá trị trước/sau; Frontend hiện toast. | L21: - A1 — Ghi đè theo node: ADMIN mở node cụ thể và đặt chính sách riêng; có nút “Gỡ ghi đè” để quay về chính sách toàn cục. - A2 — Tắt đánh giá một loại metric: các sự cố đang mở của loại đó được đóng với lý do hệ thống. | M21: - E1 — `warning ≥ critical`: `400 SOE-INC-400`; frontend chặn từ trước. - E2 — Giá trị ngoài phạm vi (0, 150, chữ): `400` kèm lỗi theo field. - E3 — Không phải ADMIN: `403`. - E4 — Hai ADMIN sửa đồng thời: `409` (optimistic concurrency); người sau phải tải lại giá trị mới nhất. | N21: chính sách mới có hiệu lực ngay cho lần đánh giá kế tiếp mà không cần khởi động lại service. | O21: BR: BR-INC-002, 005; NFR: NFR-SEC-008, FR-GW-027 | P21: TC-INC-API-015…024, TC-INC-E2E-007…009, TC-GW-SEC-011 | Q21: UC-05_incident.md
A22: 21 | B22: UC-NTF-01 | C22: Gửi cảnh báo sự cố | D22: Notification | E22: Notification Service (hệ thống) | F22: SMTP server, Webhook endpoint, Audit, Realtime | G22: Must | H22: theo số sự cố | I22: Nhận `IncidentOpenedV1` / `IncidentEscalatedV1` / `IncidentResolvedV1` | J22: Có ít nhất một kênh đang bật; cấu hình SMTP hợp lệ (với kênh email) | K22: 1. Notification nhận sự kiện sự cố. 2. Lấy danh sách kênh đang bật có `minSeverity ≤ severity` và khớp bộ lọc node/tag. 3. Với mỗi kênh, tính `deliveryId` và kiểm tra throttle (cùng sự cố + kênh + loại sự kiện trong 30 phút ⇒ bỏ qua, ghi `SKIPPED_THROTTLED`). 4. Dựng nội dung: email HTML tiếng Việt (bảng CPU/RAM/Disk có màu, khuyến nghị xử lý, liên kết sự cố) hoặc payload webhook theo `format`. 5. Gửi đi: 6. Ghi `DeliveryLogs` (`SENT`, `latencyMs`), phát `AlertDispatchedV1`; Audit ghi nhận. 7. Realtime đẩy thông báo tới giao diện người dùng đang mở (toast). | L22: - A1 — Nâng cấp mức độ: `IncidentEscalatedV1` bỏ qua throttle (người trực cần biết ngay). - A2 — Thông báo khi đóng sự cố: chỉ gửi cho kênh bật `notifyOnResolve`. - A3 — Bão sự cố: > 20 sự cố trong 5 phút ⇒ gộp thành một email tổng hợp (digest). - A4 — Kênh có bộ lọc node: chỉ gửi cho sự cố thuộc node/tag đã chọn. | M22: - E1 — Lỗi tạm thời (timeout, 5xx, SMTP 4xx): retry 3 lần backoff 1s → 4s → 16s. - E2 — Thất bại hẳn: ghi `DeliveryLogs` trạng thái `FAILED` kèm lý do rút gọn, phát `AlertFailedV1`, message vào DLQ để vận hành xử lý. - E3 — Kênh lỗi 10 lần liên tiếp: tự tắt kênh, phát `ChannelAutoDisabledV1`, thông báo ADMIN. - E4 — Webhook trỏ IP nội bộ: chặn trước khi gửi (chống SSRF), ghi `FAILED` với lý do rõ ràng. - E5 — Message xử lý lại: `deliveryId` trùng ⇒ không gửi lần hai (idempotent). - E6 — Không có kênh nào phù hợp: ghi log mức Information; sự cố vẫn hiển thị trên giao diện. | N22: mỗi sự cố có bản ghi gửi rõ ràng cho từng kênh (thành công / thất bại / bị throttle). | O22: BR: BR-NTF-001…006; NFR: NFR-PERF-010, NFR-AVL-004, NFR-SEC-009 | P22: TC-NTF-INT-001…012, TC-NTF-SEC-001…005 | Q22: UC-06_notification.md
A23: 22 | B23: UC-NTF-02 | C23: Quản lý kênh cảnh báo | D23: Notification | E23: ADMIN | I23: ADMIN mở màn hình `AlertChannels` | K23: 1. Hệ thống hiển thị danh sách kênh: tên, loại, đích nhận đã che (`o*@example.com`), mức tối thiểu, trạng thái, lần gửi gần nhất, tỷ lệ thành công 24 giờ. 2. ADMIN bấm “Thêm kênh”; chọn loại `EMAIL` hoặc `WEBHOOK`. 3. Form đổi trường theo loại: email → danh sách địa chỉ; webhook → URL, `format` (Slack/Teams/Discord/Generic), secret HMAC. 4. ADMIN đặt `minSeverity`, tùy chọn “thông báo khi đóng”, bộ lọc node/tag, trạng thái bật. 5. Frontend validate (HTTPS, không trỏ IP nội bộ, độ dài secret…). 6. Gọi `POST /alert-channels`; Notification mã hóa đích nhận và secret, lưu, trả `201`. 7. Audit ghi `CHANNEL_CREATED`; danh sách cập nhật, hiện toast. | L23: - A1 — Sửa kênh: để trống secret = giữ nguyên; `PUT /alert-channels/{id}`. - A2 — Bật/tắt nhanh: `PUT /alert-channels/{id}/status`. - A3 — Xóa kênh: hộp thoại xác nhận → `DELETE` → `204`. | M23: - E1 — Trùng tên kênh: `409 SOE-NTF-409`. - E2 — URL không phải HTTPS hoặc trỏ mạng nội bộ: `422 SOE-NTF-422` (chặn SSRF). - E3 — Email sai định dạng / quá 10 địa chỉ: `400` kèm lỗi theo field. - E4 — Không phải ADMIN: `403`. | N23: kênh sẵn sàng nhận cảnh báo; secret không bao giờ đọc lại được qua API. | P23: TC-NTF-API-001…014, TC-NTF-E2E-001…005 | Q23: UC-06_notification.md
A24: 23 | B24: UC-NTF-03 | C24: Gửi thử kênh cảnh báo | D24: Notification | E24: ADMIN | I24: ADMIN bấm “Gửi thử” | J24: kênh đã tồn tại (hoặc đang nhập trong modal) | K24: 1. Frontend gọi `POST /alert-channels/{id}/test` (rate limit 5/phút). 2. Notification dựng thông điệp mẫu “Đây là thông báo thử từ Smart Ops Engine”. 3. Gửi qua kênh tương ứng với cùng cơ chế bảo mật như cảnh báo thật. 4. Trả `{ success, latencyMs, error }`; ghi `DeliveryLogs` và Audit `CHANNEL_TESTED`. 5. Frontend hiển thị kết quả ngay trong modal và khóa nút 12 giây. | M24: - E1 — SMTP sai cấu hình: `503 SOE-NTF-503` với lý do (sai tài khoản, không kết nối được, TLS lỗi). - E2 — Webhook trả 4xx/5xx: `success = false` kèm mã trạng thái nhận được. - E3 — Gửi thử quá nhiều: `429`. - E4 — URL nội bộ: bị chặn, trả lý do bảo mật. | N24: ADMIN biết chắc kênh hoạt động trước khi có sự cố thật. | P24: TC-NTF-API-015…020, TC-NTF-SEC-006…008 | Q24: UC-06_notification.md
A25: 24 | B25: UC-NTF-04 | C25: Báo cáo sức khỏe hằng ngày | D25: Notification | E25: Scheduler (hệ thống) | F25: Metrics, Incident, SMTP | I25: Đến giờ đã cấu hình (mặc định 08:00 giờ Việt Nam) | J25: Báo cáo hằng ngày đang bật; có kênh nhận báo cáo | K25: 1. Job chạy trên một instance duy nhất (khóa phân tán). 2. Thu thập số liệu: số node đang giám sát, số node cảnh báo/nguy cấp/không liên lạc được, số sự cố đang mở, sự cố mới trong 24 giờ, số sự cố đã đóng, MTTR. 3. Dựng email HTML tiếng Việt kèm bảng tóm tắt và danh sách node đáng chú ý. 4. Gửi tới các kênh được đánh dấu “nhận báo cáo”. 5. Ghi `DeliveryLogs`, phát `DailyReportSentV1`, Audit ghi nhận. | L25: - A1 — Không có sự cố nào: báo cáo vẫn gửi với thông điệp “Hệ thống hoạt động bình thường”. - A2 — ADMIN tắt báo cáo: job bỏ qua. | M25: - E1 — SMTP lỗi: retry theo chính sách chung; thất bại thì ghi `FAILED` và cảnh báo vận hành. - E2 — Dịch vụ số liệu không phản hồi: báo cáo vẫn gửi với phần thiếu ghi “Không lấy được dữ liệu”, không bỏ hẳn báo cáo. | N25: các bên liên quan nhận được bức tranh tổng thể mỗi ngày. | P25: TC-NTF-INT-013…016, TC-NTF-API-021 | Q25: UC-06_notification.md
A26: 25 | B26: UC-RTM-01 | C26: Theo dõi cập nhật thời gian thực | D26: Realtime | E26: VIEWER / OPERATOR / ADMIN | F26: Realtime Service | G26: Must | H26: suốt phiên làm việc | I26: Ứng dụng khởi tạo sau khi đăng nhập | J26: Người dùng đã đăng nhập; trình duyệt hỗ trợ WebSocket | K26: 1. Frontend mở kết nối tới `/hubs/monitoring` kèm access token, chỉ dùng transport WebSocket. 2. Realtime xác thực token, thêm kết nối vào nhóm `authenticated` (và `admins` nếu là ADMIN). 3. Frontend gọi `SubscribeAll()` khi ở Dashboard, `SubscribeNode(nodeId)` khi vào Node Detail. 4. Khi có sự kiện (metric mới, sự cố mở/nâng cấp/xác nhận/đóng, trạng thái node đổi), Realtime đẩy tới các nhóm tương ứng. 5. Frontend ghi dữ liệu vào cache React Query, cập nhật giao diện không nhấp nháy; sự cố mới hiện toast. 6. Chỉ báo “Trực tuyến” hiển thị ở header. | L26: - A1 — Rời trang node: gọi `UnsubscribeNode(nodeId)` để giảm lưu lượng. - A2 — Kết nối lại: sau khi khôi phục, client nhận gói “trạng thái hiện tại” để đồng bộ dữ liệu đã bỏ lỡ. - A3 — Tab ẩn lâu: tạm dừng cập nhật biểu đồ, đồng bộ lại khi quay lại. | M26: - E1 — Mất kết nối: tự kết nối lại với backoff `[0, 2s, 10s, 30s]`; quá 30 giây thì bật polling 30 giây và đổi chỉ báo sang “Đang kết nối lại”. - E2 — Token hết hạn: server đóng kết nối; client refresh token rồi kết nối lại. - E3 — Vượt 10 kết nối/người dùng: kết nối cũ nhất bị đóng, client đó chuyển sang polling. - E4 — Redis backplane lỗi: mỗi instance vẫn phát cho client của mình; một phần cập nhật xuyên instance bị chậm (suy giảm có kiểm soát). - E5 — WebSocket bị chặn bởi proxy doanh nghiệp: ứng dụng vẫn dùng được nhờ polling dự phòng. | N26: người dùng thấy dữ liệu mới trong ≤ 2 giây mà không cần tải lại trang; mất realtime không làm mất chức năng. | O26: BR: BR-RTM-001…005; NFR: NFR-PERF-011, NFR-SCL-004 | P26: TC-RTM-INT-001…010, TC-RTM-E2E-001…006 | Q26: UC-07_realtime_audit_config.md
A27: 26 | B27: UC-AUD-01 | C27: Tra cứu nhật ký kiểm toán | D27: Audit | E27: ADMIN | I27: ADMIN mở màn hình `AuditLogs`, thường khi điều tra một thay đổi hoặc sự cố bảo mật | J27: đăng nhập vai trò ADMIN | K27: 1. Hệ thống hiển thị nhật ký 7 ngày gần nhất, mới nhất trước, có phân trang. 2. ADMIN lọc theo khoảng thời gian, người thực hiện, hành động, loại đối tượng, hoặc tìm theo từ khóa (debounce 300 ms). 3. Frontend gọi `GET /audit-logs` với tham số lọc; bộ lọc được lưu trong URL để chia sẻ. 4. ADMIN mở một bản ghi để xem chi tiết: giá trị trước/sau dạng diff hai cột, trường nhạy cảm hiển thị `*`, kèm `correlationId`. 5. (Tùy chọn) ADMIN mở “Dòng thời gian của đối tượng” để xem toàn bộ thao tác trên một node/sự cố. 6. (Tùy chọn) ADMIN xuất CSV; hệ thống xác nhận số dòng và ghi `AUDIT_EXPORTED`. | L27: - A1 — Kiểm tra toàn vẹn: ADMIN gọi “Kiểm tra toàn vẹn” cho một khoảng thời gian; hệ thống xác minh chuỗi băm và báo `isIntact`. - A2 — Truy vết theo correlationId: dán mã vào ô tìm kiếm để xem toàn bộ chuỗi thao tác của một request. | M27: - E1 — Khoảng thời gian > 90 ngày: `400`; frontend chặn và giải thích giới hạn. - E2 — Không phải ADMIN: không thấy mục menu; truy cập trực tiếp URL nhận `403`. - E3 — Không có kết quả: hiển thị trạng thái rỗng kèm gợi ý nới lỏng bộ lọc. - E4 — Phát hiện chuỗi băm gãy: hiển thị cảnh báo đỏ và hướng dẫn liên hệ đội bảo mật. | N27: ADMIN xác định được ai đã thay đổi gì và khi nào; chính hành động tra cứu cũng được ghi lại. | O27: BR: BR-AUD-001…006; NFR: NFR-SEC-012 | P27: TC-AUD-API-001…012, TC-AUD-E2E-001…004, TC-AUD-SEC-001…003 | Q27: UC-07_realtime_audit_config.md
A28: 27 | B28: UC-GW-01 | C28: Cấu hình hệ thống | D28: Gateway & Config | E28: ADMIN | F28: Monitoring, Incident, Notification, Audit | I28: ADMIN mở màn hình `SystemConfig` | K28: 1. Frontend gọi `GET /api/v1/system-config`; gateway tổng hợp dữ liệu từ các service sở hữu. 2. Hệ thống hiển thị 4 nhóm: Giám sát, Ngưỡng cảnh báo, Email/SMTP, Báo cáo hằng ngày, cùng trạng thái phụ thuộc (DB, RabbitMQ, Redis, SMTP). 3. ADMIN chỉnh một nhóm và bấm “Lưu” của riêng nhóm đó. 4. Frontend validate, hiển thị hộp thoại xác nhận với thay đổi nhạy cảm (tắt scheduler, đổi ngưỡng). 5. Gọi endpoint tương ứng (`/system-config/scheduler`, `/threshold-policies/global`, `/system-config/smtp`, `/system-config/daily-report`). 6. Service sở hữu validate nghiệp vụ, lưu, áp dụng ngay (không cần khởi động lại). 7. Audit ghi lại giá trị trước/sau; frontend hiện toast và cập nhật giá trị từ response. | L28: - A1 — Kiểm tra SMTP trước khi lưu: ADMIN bấm “Kiểm tra kết nối SMTP”; chỉ lưu khi thành công (hoặc xác nhận lưu kèm cảnh báo). - A2 — Tắt scheduler khẩn cấp: xác nhận hai bước; Dashboard hiển thị “Giám sát đang tạm dừng”. | M28: - E1 — Giá trị không hợp lệ (chu kỳ 10 giây, `warning ≥ critical`): `400` kèm lỗi theo field. - E2 — Một service phụ thuộc không phản hồi: nhóm cấu hình đó hiển thị “Không tải được”, các nhóm khác vẫn dùng bình thường. - E3 — Vai trò bị đổi giữa chừng: `403` ⇒ chuyển về Dashboard kèm thông báo. - E4 — Hai ADMIN sửa cùng lúc: `409`, yêu cầu tải lại. | N28: cấu hình mới có hiệu lực ngay và có dấu vết kiểm toán. | O28: BR: BR-GW-005 | P28: TC-GW-API-010…020, TC-GW-E2E-004…008 | Q28: UC-07_realtime_audit_config.md
A29: 28 | B29: UC-GW-02 | C29: Chặn truy cập trái phép | D29: Gateway & Config | E29: Gateway (hệ thống) | F29: Identity, Audit | G29: Must | H29: mỗi request | I29: Có request tới `/api/v1/` hoặc `/hubs/` | K29: 1. Gateway nhận request, sinh hoặc nhận `X-Correlation-Id`, xóa các header nhận dạng do client tự gắn. 2. Kiểm tra route có được khai báo không; không có ⇒ `404` (deny by default). 3. Kiểm tra CORS với origin trong danh sách cho phép. 4. Kiểm tra rate limit theo policy tương ứng. 5. Xác thực JWT: chữ ký RS256 theo JWKS, `iss`, `aud`, `exp`, thuật toán hợp lệ. 6. Kiểm tra policy phân quyền của route (`ViewerOrAbove` / `OperatorOrAbove` / `AdminOnly`). 7. Gắn `X-User-Id`, `X-User-Role` lấy từ token và chuyển tiếp tới service; service kiểm tra lại quyền. 8. Ghi log truy cập có cấu trúc (không ghi body, không ghi token). | M29: - E1 — Thiếu/sai token: `401` + `ProblemDetails`, không tiết lộ lý do chi tiết. - E2 — Token bị sửa chữ ký, `alg=none`, hoặc đổi sang HS256: từ chối `401`; ghi sự kiện bảo mật. - E3 — Token hợp lệ nhưng sai vai trò: `403 SOE-GW-403` “Bạn không có quyền thực hiện thao tác này.” - E4 — Vượt rate limit: `429` + `Retry-After`; vượt liên tục ⇒ ghi audit cảnh báo. - E5 — Body vượt 1 MB: `413`. - E6 — Service đích không sẵn sàng: `503`/`504` chuẩn hóa, không lộ tên service hay stack trace. - E7 — Client tự gắn `X-User-Role: ADMIN`: header bị xóa ở bước 1 ⇒ không có tác dụng nâng quyền. | N29: chỉ request hợp lệ và đúng quyền mới tới được service; mọi từ chối đều có log truy vết. | O29: BR: BR-GW-001…004; NFR: NFR-SEC-001, 008, 010, 011 | P29: TC-GW-SEC-001…020, TC-GW-API-001…009 | Q29: UC-07_realtime_audit_config.md

Sheet Use case - Từng bước
A1: Mã UC | B1: Tên use case | C1: Loại luồng | D1: Mã bước | E1: Nội dung
A2: UC-IDN-01 | B2: Đăng nhập hệ thống | C2: Luồng chính | D2: B1 | E2: Hệ thống hiển thị trang đăng nhập với ô “Tên đăng nhập”, “Mật khẩu” và nút “Đăng nhập”.
A3: UC-IDN-01 | B3: Đăng nhập hệ thống | C3: Luồng chính | D3: B2 | E3: Người dùng nhập thông tin và bấm “Đăng nhập”.
A4: UC-IDN-01 | B4: Đăng nhập hệ thống | C4: Luồng chính | D4: B3 | E4: Frontend validate: cả hai ô bắt buộc, `username` đúng định dạng. Không hợp lệ → hiện lỗi tại ô, dừng.
A5: UC-IDN-01 | B5: Đăng nhập hệ thống | C5: Luồng chính | D5: B4 | E5: Frontend gọi `POST /api/v1/auth/login`.
A6: UC-IDN-01 | B6: Đăng nhập hệ thống | C6: Luồng chính | D6: B5 | E6: Gateway kiểm tra rate limit (5 lần/phút/IP) và chuyển tiếp.
A7: UC-IDN-01 | B7: Đăng nhập hệ thống | C7: Luồng chính | D7: B6 | E7: Identity tìm người dùng, xác minh mật khẩu bằng Argon2id.
A8: UC-IDN-01 | B8: Đăng nhập hệ thống | C8: Luồng chính | D8: B7 | E8: Identity đặt lại `failedLoginCount`, cập nhật `lastLoginAt`, phát hành access token (15 phút) và refresh token (cookie `HttpOnly`), phát `UserLoggedInV1`.
A9: UC-IDN-01 | B9: Đăng nhập hệ thống | C9: Luồng chính | D9: B8 | E9: Frontend lưu access token trong bộ nhớ, khởi tạo kết nối SignalR, điều hướng tới Dashboard (hoặc `returnUrl` nội bộ).
A10: UC-IDN-01 | B10: Đăng nhập hệ thống | C10: Luồng chính | D10: B9 | E10: Audit ghi `LOGIN_SUCCEEDED`.
A11: UC-IDN-01 | B11: Đăng nhập hệ thống | C11: Luồng thay thế | D11: A1 | E11: Bắt buộc đổi mật khẩu: bước 7 trả `mustChangePassword = true` → frontend mở hộp thoại đổi mật khẩu và chặn điều hướng cho tới khi đổi xong (UC-IDN-03).
A12: UC-IDN-01 | B12: Đăng nhập hệ thống | C12: Luồng thay thế | D12: A2 | E12: Còn phiên hợp lệ: ở bước 1, nếu cookie refresh còn hạn, frontend gọi `/auth/refresh` và vào thẳng Dashboard.
... A351: UC-GW-02 | B351: Chặn truy cập trái phép | C351: Luồng ngoại lệ | D351: E7 | E351: Client tự gắn `X-User-Role: ADMIN`: header bị xóa ở bước 1 ⇒ không có tác dụng nâng quyền.

Sheet Test case v3
A1: STT | B1: Mã TC | C1: Phân hệ | D1: Nhóm / Tầng | E1: Kịch bản kiểm thử | F1: Điều kiện tiên quyết | G1: Các bước thực hiện | H1: Dữ liệu kiểm thử | I1: Kết quả mong đợi | J1: Loại | K1: Ưu tiên | L1: Truy vết (FR/BR/UC) | M1: Trạng thái | N1: Kết quả thực tế | O1: Người test | P1: Ngày test
A2: 1 | B2: TC-CON-001 | C2: Messaging & Contract | D2: Hợp đồng thông điệp (schema) — Hợp đồng thông điệp (schema) | E2: Snapshot schema mọi contract | G2: Sinh JSON schema cho tất cả type trong `SOE.Contracts` và so với bản đã lưu | I2: Không sai khác; thay đổi phá vỡ tương thích làm CI đỏ | K2: P1 - Cao | L2: R5 | M2: Chưa chạy
A3: 2 | B3: TC-CON-002 | C3: Messaging & Contract | D3: Hợp đồng thông điệp (schema) — Hợp đồng thông điệp (schema) | E3: Trường bắt buộc | G3: Deserialize message thiếu `nodeId` | I3: Thất bại với lỗi rõ ràng, message vào `_skipped` (không retry vô hạn) | K3: P1 - Cao | L3: §4.3 | M3: Chưa chạy
A4: 3 | B4: TC-CON-003 | C4: Messaging & Contract | D4: Hợp đồng thông điệp (schema) — Hợp đồng thông điệp (schema) | E4: Thêm trường tùy chọn | G4: Producer gửi `V1` có thêm trường nullable mới | I4: Consumer cũ vẫn xử lý bình thường | K4: P1 - Cao | L4: R2 | M4: Chưa chạy
A5: 4 | B5: TC-CON-004 | C5: Messaging & Contract | D5: Hợp đồng thông điệp (schema) — Hợp đồng thông điệp (schema) | E5: Song song V1 và V2 | G5: Publish cả hai phiên bản | I5: Consumer tương ứng nhận đúng phiên bản, không nhầm lẫn | K5: P2 - Trung bình | L5: R3 | M5: Chưa chạy
A6: 5 | B6: TC-CON-005 | C6: Messaging & Contract | D6: Hợp đồng thông điệp (schema) — Hợp đồng thông điệp (schema) | E6: Thời gian là UTC | G6: Kiểm tra mọi trường thời gian trong contract | I6: Kiểu `DateTimeOffset`, giá trị UTC, serialize ISO-8601 | K6: P1 - Cao | L6: Quy ước §5 | M6: Chưa chạy
A7: 6 | B7: TC-CON-006 | C7: Messaging & Contract | D7: Hợp đồng thông điệp (schema) — Hợp đồng thông điệp (schema) | E7: Không mang bí mật | G7: Rà soát mọi contract | I7: Không có trường credential/token/secret | K7: P1 - Cao | L7: §6, ADR-04 | M7: Chưa chạy
A8: 7 | B8: TC-CON-007 | C8: Messaging & Contract | D8: Hợp đồng thông điệp (schema) — Hợp đồng thông điệp (schema) | E8: Kích thước message | G8: Sinh message lớn nhất có thể (mô tả dài nhất) | I8: ≤ 256 KB | K8: P2 - Trung bình | L8: §6 | M8: Chưa chạy
A9: 8 | B9: TC-CON-008 | C9: Messaging & Contract | D9: Hợp đồng thông điệp (schema) — Hợp đồng thông điệp (schema) | E9: Đặt tên đúng quy ước | G9: Kiểm tra tên type và queue | I9: Theo bảng quy ước §2 | K9: P3 - Thấp | L9: §2 | M9: Chưa chạy
A10: 9 | B10: TC-CON-011 | C10: Messaging & Contract | D10: Outbox / Inbox / Idempotency — Outbox / Inbox / Idempotency | E10: Outbox commit cùng transaction | G10: Tạo node thành công | I10: Bản ghi node và bản ghi outbox cùng tồn tại; event được publish sau commit | K10: P1 - Cao | L10: §4.1 | M10: Chưa chạy
A11: 10 | B11: TC-CON-012 | C11: Messaging & Contract | D11: Outbox / Inbox / Idempotency — Outbox / Inbox / Idempotency | E11: Rollback không phát event | G11: Ép lỗi sau khi ghi outbox | I11: Không có node, không có event trên broker | K11: P1 - Cao | L11: NFR-AVL-002 | M11: Chưa chạy
A12: 11 | B12: TC-CON-013 | C12: Messaging & Contract | D12: Outbox / Inbox / Idempotency — Outbox / Inbox / Idempotency | E12: Broker ngừng khi publish | G12: Dừng RabbitMQ, tạo node, bật lại | I12: Event nằm trong outbox và được phát khi broker trở lại | K12: P1 - Cao | L12: NFR-AVL-004 | M12: Chưa chạy
A13: 12 | B13: TC-CON-014 | C13: Messaging & Contract | D13: Outbox / Inbox / Idempotency — Outbox / Inbox / Idempotency | E13: Inbox chống trùng | G13: Gửi cùng `MessageId` 5 lần | I13: Consumer xử lý đúng 1 lần (`InboxState` ghi nhận) | K13: P1 - Cao | L13: §4.2 | M13: Chưa chạy
... A31: 30 | B31: TC-CON-045 | C31: Messaging & Contract | D31: Kiểm thử tích hợp xuyên service (end-to-end đường ống) — Kiểm thử tích hợp xuyên service (end-to-end đường ống) | E31: Một `correlationId` xuyên suốt | G31: Thực hiện một thao tác ghi | I31: Cùng `correlationId` xuất hiện ở log gateway, service, consumer và bản ghi audit | K31: P1 - Cao | L31: NFR-OBS-001 | M31: Chưa chạy
A32: 31 | B32: TC-PERF-API-001 | C32: Performance & Scaling | D32: API — Hiệu năng API (k6) | E32: `GET /nodes` phân trang | H32: 30 VU, 5 phút | I32: p95 ≤ 300 ms, lỗi 0% | K32: P1 - Cao | L32: NFR-PERF-001 | M32: Chưa chạy
A33: 32 | B33: TC-PERF-API-002 | C33: Performance & Scaling | D33: API — Hiệu năng API (k6) | E33: `GET /metrics/latest` (500 node) | H33: 30 VU, 5 phút | I33: p95 ≤ 400 ms | K33: P1 - Cao | L33: NFR-PERF-003 | M33: Chưa chạy
A34: 33 | B34: TC-PERF-API-003 | C34: Performance & Scaling | D34: API — Hiệu năng API (k6) | E34: `GET /nodes/{id}/metrics?range=30d` | H34: 20 VU, 5 phút | I34: p95 ≤ 700 ms, ≤ 500 điểm/phản hồi | K34: P1 - Cao | L34: NFR-PERF-004 | M34: Chưa chạy
A35: 34 | B35: TC-PERF-API-004 | C35: Performance & Scaling | D35: API — Hiệu năng API (k6) | E35: `GET /incidents` với 100.000 bản ghi | H35: 20 VU | I35: p95 ≤ 300 ms | K35: P1 - Cao | L35: NFR-PERF-001 | M35: Chưa chạy
A36: 35 | B36: TC-PERF-API-005 | C36: Performance & Scaling | D36: API — Hiệu năng API (k6) | E36: Ghi: tạo/sửa node | H36: 10 VU | I36: p95 ≤ 500 ms | K36: P2 - Trung bình | L36: NFR-PERF-002 | M36: Chưa chạy
A37: 36 | B37: TC-PERF-API-006 | C37: Performance & Scaling | D37: API — Hiệu năng API (k6) | E37: Đăng nhập (Argon2id) | H37: 10 VU | I37: p95 ≤ 700 ms, CPU Identity < 80% | K37: P2 - Trung bình | L37: SRS IDN §10 | M37: Chưa chạy
A38: 37 | B38: TC-PERF-API-007 | C38: Performance & Scaling | D38: API — Hiệu năng API (k6) | E38: Hỗn hợp thực tế (80% đọc / 20% ghi) | H38: 50 VU, 15 phút | I38: p95 tổng ≤ 400 ms, lỗi < 0,1% | K38: P1 - Cao | L38: NFR-PERF-001 | M38: Chưa chạy
A39: 38 | B39: TC-PERF-API-008 | C39: Performance & Scaling | D39: API — Hiệu năng API (k6) | E39: Spike test | H39: 10 → 200 VU trong 30 giây | I39: Không lỗi 5xx kéo dài; hệ thống hồi phục < 2 phút | K39: P2 - Trung bình | L39: NFR-AVL-001 | M39: Chưa chạy
A40: 39 | B40: TC-PERF-API-009 | C40: Performance & Scaling | D40: API — Hiệu năng API (k6) | E40: Soak test | H40: 30 VU, 4 giờ | I40: Không rò rỉ bộ nhớ (RSS ổn định), không tăng độ trễ theo thời gian | K40: P2 - Trung bình | L40: NFR-MNT | M40: Chưa chạy
A41: 40 | B41: TC-PERF-MON-001 | C41: Performance & Scaling | D41: Performance — Đường ống giám sát | E41: Độ phủ chu kỳ 500 node | G41: Chạy 10 chu kỳ 5 phút với 2 worker | I41: ≥ 99% node được quét mỗi chu kỳ | K41: P1 - Cao | L41: NFR-SCL-001 | M41: Chưa chạy
A42: 41 | B42: TC-PERF-MON-002 | C42: Performance & Scaling | D42: Performance — Đường ống giám sát | E42: Thời gian một lần quét | G42: Đo `soe_check_duration_seconds` | I42: p95 ≤ 5 giây | K42: P1 - Cao | L42: NFR-PERF-005 | M42: Chưa chạy
A43: 42 | B43: TC-PERF-MON-003 | C43: Performance & Scaling | D43: Performance — Đường ống giám sát | E43: Mở rộng ngang worker | G43: Chạy cùng tải với 2 → 4 → 8 worker | I43: Thời gian hoàn tất chu kỳ giảm ≥ 40% khi gấp đôi worker (tới khi chạm giới hạn DB) | K43: P1 - Cao | L43: NFR-SCL-002 | M43: Chưa chạy
A44: 43 | B44: TC-PERF-MON-004 | C44: Performance & Scaling | D44: Performance — Đường ống giám sát | E44: KEDA tự scale | G44: Bơm 5.000 lệnh quét vào queue | I44: Số pod worker tăng theo độ sâu queue (20 msg/pod), tối đa 30; giảm lại sau `cooldownPeriod` | K44: P1 - Cao | L44: deployment §4 | M44: Chưa chạy
A45: 44 | B45: TC-PERF-MON-005 | C45: Performance & Scaling | D45: Performance — Đường ống giám sát | E45: Quy mô 2.000 node | G45: Tăng số node giả lập | I45: Vẫn đạt độ phủ ≥ 99% với ≤ 10 worker | K45: P2 - Trung bình | L45: NFR-SCL-003 | M45: Chưa chạy
A46: 45 | B46: TC-PERF-MON-006 | C46: Performance & Scaling | D46: Performance — Đường ống giám sát | E46: Ghi metric 1.000/phút | G46: Bơm event | I46: Queue `metrics.metric-collected` không dồn > 500; CPU pod < 70% | K46: P1 - Cao | L46: NFR-SCL-005 | M46: Chưa chạy
A47: 46 | B47: TC-PERF-MON-007 | C47: Performance & Scaling | D47: Performance — Đường ống giám sát | E47: Độ trễ cảnh báo đầu-cuối | G47: Kích hoạt vượt ngưỡng trên 50 node đồng thời | I47: p95 từ `collectedAt` tới lúc email/webhook rời hệ thống ≤ 60 giây | K47: P1 - Cao | L47: NFR-PERF-010 | M47: Chưa chạy
A48: 47 | B48: TC-PERF-MON-008 | C48: Performance & Scaling | D48: Performance — Đường ống giám sát | E48: Node chậm không chặn node khác | G48: 50 node treo (timeout 30s) + 450 node bình thường | I48: Node bình thường vẫn được quét đúng hạn | K48: P1 - Cao | L48: NFR-AVL-005 | M48: Chưa chạy
A49: 48 | B49: TC-PERF-RTM-001 | C49: Performance & Scaling | D49: Performance — Realtime & Frontend | E49: 200 kết nối SignalR | G49: Công cụ tạo tải WebSocket | I49: CPU pod < 60%, p95 độ trễ đẩy ≤ 2 giây, 0 kết nối rớt | K49: P1 - Cao | L49: NFR-SCL-004 | M49: Chưa chạy
A50: 49 | B50: TC-PERF-FE-001 | C50: Performance & Scaling | D50: Performance — Realtime & Frontend | E50: LCP Dashboard | G50: Lighthouse CI, Fast 3G mô phỏng, 500 node | I50: LCP ≤ 2,5 giây | K50: P1 - Cao | L50: NFR-PERF-020 | M50: Chưa chạy
A51: 50 | B51: TC-PERF-FE-002 | C51: Performance & Scaling | D51: Performance — Realtime & Frontend | E51: INP | G51: Lighthouse CI + thao tác lọc/chuyển trang | I51: INP ≤ 200 ms | K51: P1 - Cao | L51: NFR-PERF-021 | M51: Chưa chạy
A52: 51 | B52: TC-PERF-FE-003 | C52: Performance & Scaling | D52: Performance — Realtime & Frontend | E52: CLS | G52: Lighthouse CI | I52: ≤ 0,1 | K52: P2 - Trung bình | L52: NFR-PERF-022 | M52: Chưa chạy
... A84: 83 | B84: TC-SEC-API10-001 | C84: Security | D84: Security — OWASP API Security Top 10 | E84: Phản hồi bên ngoài độc hại | G84: Webhook trả body 10 MB / JSON lồng sâu | I84: Chỉ đọc 8 KB, không parse, không treo | K84: P2 - Trung bình | L84: OWASP API10 | M84: Chưa chạy
A85: 84 | B85: TC-SEC-INJ-001 | C85: Security | D85: Security — Injection & xử lý dữ liệu | E85: SQL injection ở mọi tham số lọc (`search='; DROP TABLE…`) | I85: Không thực thi; EF Core tham số hóa; trả kết quả rỗng hoặc 400 | K85: P1 - Cao | L85: §7 gateway | M85: Chưa chạy
A86: 85 | B86: TC-SEC-INJ-002 | C86: Security | D86: Security — Injection & xử lý dữ liệu | E86: Command injection qua `host`, `username`, `diskMountPath` (`; rm -rf /`, `$(id)`, backtick) | I86: Bị validate chặn; lệnh SSH không bị thay đổi | K86: P1 - Cao | L86: BR-MON-001 | M86: Chưa chạy
